{
  "nbformat": 4,
  "nbformat_minor": 0,
  "metadata": {
    "colab": {
      "provenance": [],
      "authorship_tag": "ABX9TyPR6elLOJbSMNyXcgRBlpex",
      "include_colab_link": true
    },
    "kernelspec": {
      "name": "python3",
      "display_name": "Python 3"
    },
    "language_info": {
      "name": "python"
    }
  },
  "cells": [
    {
      "cell_type": "markdown",
      "metadata": {
        "id": "view-in-github",
        "colab_type": "text"
      },
      "source": [
        "<a href=\"https://colab.research.google.com/github/sushankhadka12/AI-Lab1-sushankhadka02139/blob/main/KNN.ipynb\" target=\"_parent\"><img src=\"https://colab.research.google.com/assets/colab-badge.svg\" alt=\"Open In Colab\"/></a>"
      ]
    },
    {
      "cell_type": "code",
      "execution_count": 1,
      "metadata": {
        "id": "r2AjnzkUUKPY"
      },
      "outputs": [],
      "source": [
        "import pandas as pd\n"
      ]
    },
    {
      "cell_type": "code",
      "source": [
        "!pwd\n"
      ],
      "metadata": {
        "colab": {
          "base_uri": "https://localhost:8080/"
        },
        "id": "B5962hycUguj",
        "outputId": "25b21bcb-91fe-436b-9be3-0d08fea13156"
      },
      "execution_count": 2,
      "outputs": [
        {
          "output_type": "stream",
          "name": "stdout",
          "text": [
            "/content\n"
          ]
        }
      ]
    },
    {
      "cell_type": "code",
      "source": [
        "!pip install automl"
      ],
      "metadata": {
        "colab": {
          "base_uri": "https://localhost:8080/"
        },
        "id": "eB9YsJAZUrK0",
        "outputId": "611ecf4c-9354-4641-8e55-afc14cee83f8"
      },
      "execution_count": 3,
      "outputs": [
        {
          "output_type": "stream",
          "name": "stdout",
          "text": [
            "Collecting automl\n",
            "  Downloading automl-2.9.9-py2.py3-none-any.whl.metadata (11 kB)\n",
            "Collecting dill<0.3,>=0.2.5 (from automl)\n",
            "  Downloading dill-0.2.9.tar.gz (150 kB)\n",
            "\u001b[2K     \u001b[90m━━━━━━━━━━━━━━━━━━━━━━━━━━━━━━━━━━━━━━━\u001b[0m \u001b[32m150.7/150.7 kB\u001b[0m \u001b[31m3.6 MB/s\u001b[0m eta \u001b[36m0:00:00\u001b[0m\n",
            "\u001b[?25h  Preparing metadata (setup.py) ... \u001b[?25l\u001b[?25hdone\n",
            "Collecting h5py<3.0,>=2.7.0 (from automl)\n",
            "  Downloading h5py-2.10.0.tar.gz (301 kB)\n",
            "\u001b[2K     \u001b[90m━━━━━━━━━━━━━━━━━━━━━━━━━━━━━━━━━━━━━━\u001b[0m \u001b[32m301.1/301.1 kB\u001b[0m \u001b[31m13.1 MB/s\u001b[0m eta \u001b[36m0:00:00\u001b[0m\n",
            "\u001b[?25h  Preparing metadata (setup.py) ... \u001b[?25l\u001b[?25hdone\n",
            "Collecting lightgbm<2.1,>=2.0.11 (from automl)\n",
            "  Downloading lightgbm-2.0.12-py2.py3-none-manylinux1_x86_64.whl.metadata (6.4 kB)\n",
            "Collecting numpy<2.0,>=1.11.0 (from automl)\n",
            "  Downloading numpy-1.26.4-cp311-cp311-manylinux_2_17_x86_64.manylinux2014_x86_64.whl.metadata (61 kB)\n",
            "\u001b[2K     \u001b[90m━━━━━━━━━━━━━━━━━━━━━━━━━━━━━━━━━━━━━━━━\u001b[0m \u001b[32m61.0/61.0 kB\u001b[0m \u001b[31m3.9 MB/s\u001b[0m eta \u001b[36m0:00:00\u001b[0m\n",
            "\u001b[?25hCollecting pandas<1.0,>=0.18.0 (from automl)\n",
            "  Downloading pandas-0.25.3.tar.gz (12.6 MB)\n",
            "\u001b[2K     \u001b[90m━━━━━━━━━━━━━━━━━━━━━━━━━━━━━━━━━━━━━━━━\u001b[0m \u001b[32m12.6/12.6 MB\u001b[0m \u001b[31m97.8 MB/s\u001b[0m eta \u001b[36m0:00:00\u001b[0m\n",
            "\u001b[?25h  \u001b[1;31merror\u001b[0m: \u001b[1msubprocess-exited-with-error\u001b[0m\n",
            "  \n",
            "  \u001b[31m×\u001b[0m \u001b[32mpython setup.py egg_info\u001b[0m did not run successfully.\n",
            "  \u001b[31m│\u001b[0m exit code: \u001b[1;36m1\u001b[0m\n",
            "  \u001b[31m╰─>\u001b[0m See above for output.\n",
            "  \n",
            "  \u001b[1;35mnote\u001b[0m: This error originates from a subprocess, and is likely not a problem with pip.\n",
            "  Preparing metadata (setup.py) ... \u001b[?25l\u001b[?25herror\n",
            "\u001b[1;31merror\u001b[0m: \u001b[1mmetadata-generation-failed\u001b[0m\n",
            "\n",
            "\u001b[31m×\u001b[0m Encountered error while generating package metadata.\n",
            "\u001b[31m╰─>\u001b[0m See above for output.\n",
            "\n",
            "\u001b[1;35mnote\u001b[0m: This is an issue with the package mentioned above, not pip.\n",
            "\u001b[1;36mhint\u001b[0m: See above for details.\n"
          ]
        }
      ]
    },
    {
      "cell_type": "code",
      "source": [],
      "metadata": {
        "id": "6tfjxhKsVknr"
      },
      "execution_count": null,
      "outputs": []
    }
  ]
}